#!/usr/local/bin/python3
""" Named and generic exception handling"""

def add(a,b):
    """ Print the results of adding a set and a value"""
    try:
        a.add(b)
        print(a)
    except AttributeError:
        print("({0}) is not a set object".format(a))
    except TypeError:
        print("({0}) is not a hashable object".format(b))
    except:
        print("This is a generic exception")

class Test(object):
    """ just a Simple test class """

    def add(self, a):
        """ Demonstrates how you need to be able to handle unpredictable results. """
        d = {'python':'fun'}
        return d[a]

if __name__ == "__main__":
    s = set((1,2,3))
    add(s,4)
    add(1,4)
    add(s, [4,5,6])
    t = Test()
    add(t, 1)
